Workbook

Sheet Introduction
B3: STM OCE-P to Vault CRM Migration - Calls
B5: WIP v0.1
B8: Reviewer | C8: Role
B9: Aline Machado | C9: BO
B10: Aleksandra Bujwid | C10: Core BA

Sheet Data_Models
B1: Veeva Account and Call Data Model | K1: OCE-P Call Data Model

Sheet SRC - OCE-P Objects
A1: Object | B1: Object Label | C1: Object Description | D1: Ownership
A2: OCE__Call__c | B2: Interactions | C2: The Call object stores all data pertaining to Calls Reps have logged using the Log a Call module.
A3: OCE__CallDetail__c | B3: Interaction Details | C3: The object stores data related to Details during the Call | D3: Sutapa/Swaroop
A4: OCE__CallDiscussion__c | B4: Call Discussions | C4: The object stores data related to Discussions about products, during the Call | D4: Sutapa/Swaroop
A5: OCE__CallMessage__c | B5: Call Messages | C5: The object stores data related to messages/reactions during the Call | D5: Sutapa/Swaroop
A6: OCE__CallEmployeeAttendee__c | B6: Call Employee Attendees | C6: Junction object which contains users which are added as attendees to call.
A7: OCE__CallItem__c | B7: Call Items | C7: The object stores data related to Items during the Call
A8: OCE__CallPresentation__c | B8: Call Presentations | C8: The object stores data related to Presentations shown from Call, Meeting, etc.
A9: OCE__CallDialogue__c | B9: Interaction Dialogues | C9: Contains surveys passed on LogACall.
A10: OCE__CallSampleOrder__c | B10: Call Sample Orders | C10: The object stores data related to Sample Orders during the Call
A11: OCE__CallStudy__c | B11: Interaction clinical trials | C11: Studies which were done during call.
A12: OCE__CallToDo__c | B12: Interaction To-Dos | C12: Junction object between Call and To-Do objects
A13: OCE__CallAccountTactic__c | B13: Interaction Tactics | C13: Junction object to connect Call to Tactics.
A14: OCE__CallSample__c | B14: Call Samples | C14: The object stores data related to Samples during the Call
A15: OCE__CallPlan__c | B15: Call Plans | C15: A strategic plan that is focused on reach and frequency.
A16: OCE__CallExpense__c | B16: Call Expenses | C16: The object stores data related to Expenses during the Call

Sheet TGT - Vault CRM Objects
A1: Object | B1: Object Label | C1: Object Description
A2: call2__v | B2: Call | C2: This object stores the main call header information. There is one call row for every account or contact on the call. A group call with 3 doctors will produce 4 call rows.
A3: call2_detail__v | B3: Call Detail | C3: This object stores all product details data recorded on any call.
A4: call2_discussion__v | B4: Call Discussion | C4: This object stores all product discussions data recorded on any call, as well as allows for creating different product discussions layouts
A5: call2_expense__v | B5: Call Expense | C5: This object stores all expense data recorded on a call
A6: call2_key_message__v | B6: Call Key Message | C6: This object stores all Key Messages recorded on a call
A7: call2_sample__v | B7: Call Sample | C7: Samples and Promotional Items itemized on Call Reports
A8: call2_sample_cancel__v | B8: Call Sample Cancel | C8: The Call Sample Cancel object provides the ability to Cancel the delivery of a Sample Send request for a physician.
A9: call_clickstream__v | B9: Call Clickstream | C9: Object containing clickstream data received from CLM system.
A10: call_cycle_entry__v | B10: Call Cycle Entry | C10: Call Cycle Entries store information about a rep's weekly route. They only store account name, the default address for each account is used when the call cycle is applied to a day. Call cycles (and their titles) are only editable on VMobile. However, r
A11: call_error__v | B11: Call Error | C11: This is a temporary holding object for failed synchronization messages from the mobile client. The messages will be accepted or rejected by an administrator.
A12: call_followup_task__v | B12: Call Followup Task | C12: This is the user task object that stores records for call follow up activities.
... A14: call_objective__v | B14: Call Objective | C14: Call Objective can be accessed through Call Report

Sheet SRC - OCE-P Object Fields
A1: _ | B1: EntityDefinition | C1: EntityDefinition.QualifiedApiName | D1: DurableId | E1: Label | F1: QualifiedApiName | G1: DataType | H1: RelationshipName | I1: ExtraTypeInfo | J1: Length | K1: Precision | L1: ValueTypeId | M1: IsIndexed | N1: IsNillable | O1: IsCompound | P1: IsHighScaleNumber | Q1: IsHtmlFormatted | R1: IsCalculated | S1: Description
A2: [FieldDefinition] | B2: [EntityDefinition] | C2: OCE__CallItem__c | D2: 01I3X000001zXyY.UserRecordAccess | E2: Object Access Level | F2: UserRecordAccessId | G2: Lookup(User Record Access) | H2: UserRecordAccess | J2: 18 | K2: 0 | L2: id | M2: false | N2: true | O2: false | P2: false | Q2: false | R2: false
A3: [FieldDefinition] | B3: [EntityDefinition] | C3: OCE__CallItem__c | D3: 01I3X000001zXyY.SystemModstamp | E3: System Modstamp | F3: SystemModstamp | G3: Date/Time | J3: 0 | K3: 0 | L3: datetime | M3: true | N3: false | O3: false | P3: false | Q3: false | R3: false
A4: [FieldDefinition] | B4: [EntityDefinition] | C4: OCE__CallItem__c | D4: 01I3X000001zXyY.Owner | E4: Owner | F4: OwnerId | G4: Lookup(User,Group) | H4: Owner | J4: 18 | K4: 0 | L4: id | M4: true | N4: false | O4: false | P4: false | Q4: false | R4: false
A5: [FieldDefinition] | B5: [EntityDefinition] | C5: OCE__CallItem__c | D5: 01I3X000001zXyY.Name | E5: Interaction Item Name | F5: Name | G5: Auto Number | J5: 80 | K5: 0 | L5: string | M5: true | N5: false | O5: false | P5: false | Q5: false | R5: false
A6: [FieldDefinition] | B6: [EntityDefinition] | C6: OCE__CallItem__c | D6: 01I3X000001zXyY.LastModifiedDate | E6: Last Modified Date | F6: LastModifiedDate | G6: Date/Time | J6: 0 | K6: 0 | L6: datetime | M6: false | N6: false | O6: false | P6: false | Q6: false | R6: false
A7: [FieldDefinition] | B7: [EntityDefinition] | C7: OCE__CallItem__c | D7: 01I3X000001zXyY.LastModifiedBy | E7: Last Modified By | F7: LastModifiedById | G7: Lookup(User) | H7: LastModifiedBy | J7: 18 | K7: 0 | L7: id | M7: false | N7: false | O7: false | P7: false | Q7: false | R7: false
A8: [FieldDefinition] | B8: [EntityDefinition] | C8: OCE__CallItem__c | D8: 01I3X000001zXyY.LastActivityDate | E8: Last Activity Date | F8: LastActivityDate | G8: Date | J8: 0 | K8: 0 | L8: date | M8: false | N8: true | O8: false | P8: false | Q8: false | R8: false
A9: [FieldDefinition] | B9: [EntityDefinition] | C9: OCE__CallItem__c | D9: 01I3X000001zXyY.IsDeleted | E9: Deleted | F9: IsDeleted | G9: Checkbox | J9: 0 | K9: 0 | L9: boolean | M9: true | N9: false | O9: false | P9: false | Q9: false | R9: false
A10: [FieldDefinition] | B10: [EntityDefinition] | C10: OCE__CallItem__c | D10: 01I3X000001zXyY.Id | E10: Record ID | F10: Id | G10: Lookup() | J10: 18 | K10: 0 | L10: id | M10: true | N10: false | O10: false | P10: false | Q10: false | R10: false
A11: [FieldDefinition] | B11: [EntityDefinition] | C11: OCE__CallItem__c | D11: 01I3X000001zXyY.CurrencyIsoCode | E11: Currency | F11: CurrencyIsoCode | G11: Picklist | J11: 3 | K11: 0 | L11: string | M11: false | N11: true | O11: false | P11: false | Q11: false | R11: false
A12: [FieldDefinition] | B12: [EntityDefinition] | C12: OCE__CallItem__c | D12: 01I3X000001zXyY.CreatedDate | E12: Created Date | F12: CreatedDate | G12: Date/Time | J12: 0 | K12: 0 | L12: datetime | M12: true | N12: false | O12: false | P12: false | Q12: false | R12: false
A13: [FieldDefinition] | B13: [EntityDefinition] | C13: OCE__CallItem__c | D13: 01I3X000001zXyY.CreatedBy | E13: Created By | F13: CreatedById | G13: Lookup(User) | H13: CreatedBy | J13: 18 | K13: 0 | L13: id | M13: false | N13: false | O13: false | P13: false | Q13: false | R13: false
A14: [FieldDefinition] | B14: [EntityDefinition] | C14: OCE__CallItem__c | D14: 01I3X000001zXyY.00N3X00000ML0H8 | E14: Value | F14: Value__c | G14: Number(16, 2) | J14: 0 | K14: 18 | L14: double | M14: false | N14: true | O14: false | P14: false | Q14: false | R14: false
A15: [FieldDefinition] | B15: [EntityDefinition] | C15: OCE__CallItem__c | D15: 01I3X000001zXyY.00N3X00000ML0H7 | E15: Interaction Status | F15: RCH_Call_Status__c | G15: Formula (Text) | J15: 1300 | K15: 0 | L15: string | M15: false | N15: true | O15: false | P15: false | Q15: false | R15: true | S15: Status of the Parent Call
A16: [FieldDefinition] | B16: [EntityDefinition] | C16: OCE__CallItem__c | D16: 01I3X000001zXyY.00N3X00000JUTxF | E16: Unique Integration ID | F16: OCE__UniqueIntegrationID__c | G16: Text(100) (External ID) (Unique Case Sensitive) | J16: 100 | K16: 0 | L16: string | M16: true | N16: true | O16: false | P16: false | Q16: false | R16: false | S16: Unique External ID which is used for data loading only.
A17: [FieldDefinition] | B17: [EntityDefinition] | C17: OCE__CallItem__c | D17: 01I3X000001zXyY.00N3X00000JUTxE | E17: Qty | F17: OCE__Quantity__c | G17: Number(18, 0) | J17: 0 | K17: 18 | L17: double | M17: false | N17: false | O17: false | P17: false | Q17: false | R17: false | S17: The number of Promotional Items disbursed
A18: [FieldDefinition] | B18: [EntityDefinition] | C18: OCE__CallItem__c | D18: 01I3X000001zXyY.00N3X00000JUTxD | E18: Product | F18: OCE__Product__c | G18: Lookup(Product) | H18: OCE__Product__r | J18: 18 | K18: 0 | L18: id | M18: true | N18: true | O18: false | P18: false | Q18: false | R18: false | S18: The Product associated with the CallItem
A19: [FieldDefinition] | B19: [EntityDefinition] | C19: OCE__CallItem__c | D19: 01I3X000001zXyY.00N3X00000JUTxC | E19: Product Ref Data | F19: OCE__ProductRefData__c | G19: Text(255) | J19: 255 | K19: 0 | L19: string | M19: false | N19: true | O19: false | P19: false | Q19: false | R19: false | S19: Denormalized product name.
A20: [FieldDefinition] | B20: [EntityDefinition] | C20: OCE__CallItem__c | D20: 01I3X000001zXyY.00N3X00000JUTxB | E20: Offline Unique Id | F20: OCE__OfflineUniqueId__c | G20: Text(255) (External ID) | J20: 255 | K20: 0 | L20: string | M20: true | N20: true | O20: false | P20: false | Q20: false | R20: false | S20: Globally unique string that identifies an offline created record.
A21: [FieldDefinition] | B21: [EntityDefinition] | C21: OCE__CallItem__c | D21: 01I3X000001zXyY.00N3X00000JUTxA | E21: Offline Last Modified Date | F21: OCE__OfflineLastModifiedDate__c | G21: Date/Time | J21: 0 | K21: 0 | L21: datetime | M21: false | N21: true | O21: false | P21: false | Q21: false | R21: false | S21: Offline Last Modified Date
A22: [FieldDefinition] | B22: [EntityDefinition] | C22: OCE__CallItem__c | D22: 01I3X000001zXyY.00N3X00000JUTx9 | E22: Offline Last Modified By Id | F22: OCE__OfflineLastModifiedByID__c | G22: Lookup(User) | H22: OCE__OfflineLastModifiedByID__r | J22: 18 | K22: 0 | L22: id | M22: true | N22: true | O22: false | P22: false | Q22: false | R22: false | S22: Offline Last Modified By ID
A23: [FieldDefinition] | B23: [EntityDefinition] | C23: OCE__CallItem__c | D23: 01I3X000001zXyY.00N3X00000JUTx8 | E23: Offline Created Date | F23: OCE__OfflineCreatedDate__c | G23: Date/Time | J23: 0 | K23: 0 | L23: datetime | M23: false | N23: true | O23: false | P23: false | Q23: false | R23: false | S23: Offline Created Date
A24: [FieldDefinition] | B24: [EntityDefinition] | C24: OCE__CallItem__c | D24: 01I3X000001zXyY.00N3X00000JUTx7 | E24: Offline Created By Id | F24: OCE__OfflineCreatedByID__c | G24: Lookup(User) | H24: OCE__OfflineCreatedByID__r | J24: 18 | K24: 0 | L24: id | M24: true | N24: true | O24: false | P24: false | Q24: false | R24: false | S24: Offline Created By ID
A25: [FieldDefinition] | B25: [EntityDefinition] | C25: OCE__CallItem__c | D25: 01I3X000001zXyY.00N3X00000JUTx6 | E25: Item | F25: OCE__Item__c | G25: Lookup(Product) | H25: OCE__Item__r | J25: 18 | K25: 0 | L25: id | M25: true | N25: true | O25: false | P25: false | Q25: false | R25: false | S25: The name of the Product for which Item being disbursed. This is used to link a Product to a Call Item.
A26: [FieldDefinition] | B26: [EntityDefinition] | C26: OCE__CallItem__c | D26: 01I3X000001zXyY.00N3X00000JUTx5 | E26: Item Ref Data | F26: OCE__ItemRefData__c | G26: Text(255) | J26: 255 | K26: 0 | L26: string | M26: false | N26: true | O26: false | P26: false | Q26: false | R26: false | S26: Denormalized product name.
A27: [FieldDefinition] | B27: [EntityDefinition] | C27: OCE__CallItem__c | D27: 01I3X000001zXyY.00N3X00000JUTx4 | E27: Is Signature Captured? | F27: OCE__IsSignatureCaptured__c | G27: Checkbox | J27: 0 | K27: 0 | L27: boolean | M27: false | N27: false | O27: false | P27: false | Q27: false | R27: false | S27: Track if record was on call on sign.
A28: [FieldDefinition] | B28: [EntityDefinition] | C28: OCE__CallItem__c | D28: 01I3X000001zXyY.00N3X00000JUTx3 | E28: Integration Id | F28: OCE__IntegrationId__c | G28: Text(100) | J28: 100 | K28: 0 | L28: string | M28: false | N28: true | O28: false | P28: false | Q28: false | R28: false | S28: External ID which is used for data loading only.
A29: [FieldDefinition] | B29: [EntityDefinition] | C29: OCE__CallItem__c | D29: 01I3X000001zXyY.00N3X00000JUTx2 | E29: Interaction | F29: OCE__Call__c | G29: Lookup(Interaction) | H29: OCE__Call__r | J29: 18 | K29: 0 | L29: id | M29: true | N29: false | O29: false | P29: false | Q29: false | R29: false | S29: The Call associated with the CallItem
A30: [FieldDefinition] | B30: [EntityDefinition] | C30: OCE__CallItem__c | D30: 01I3X000001zXyY.00N3X00000JUTx1 | E30: Interaction Ref Data | F30: OCE__CallRefData__c | G30: Text(255) | J30: 255 | K30: 0 | L30: string | M30: false | N30: true | O30: false | P30: false | Q30: false | R30: false | S30: Denormalized call name.
A31: [FieldDefinition] | B31: [EntityDefinition] | C31: OCE__CallItem__c | D31: 01I3X000001zXyY.00N3X00000JUTx0 | E31: Account | F31: OCE__Account__c | G31: Lookup(Account) | H31: OCE__Account__r | J31: 18 | K31: 0 | L31: id | M31: true | N31: true | O31: false | P31: false | Q31: false | R31: false | S31: The Account for which the Item was disbursed. This is used to link an Account to a Call Item.
A32: [FieldDefinition] | B32: [EntityDefinition] | C32: OCE__CallItem__c | D32: 01I3X000001zXyY.00N3X00000JUTwz | E32: Account Territories | F32: OCE__AccountTerritories__c | G32: Text(255) | J32: 255 | K32: 0 | L32: string | M32: false | N32: true | O32: false | P32: false | Q32: false | R32: false | S32: Territories associated with Account.
A33: [FieldDefinition] | B33: [EntityDefinition] | C33: OCE__CallItem__c | D33: 01I3X000001zXyY.00N3X00000JUTwy | E33: Account Ref Data | F33: OCE__AccountRefData__c | G33: Text(255) | J33: 255 | K33: 0 | L33: string | M33: false | N33: true | O33: false | P33: false | Q33: false | R33: false | S33: Denormalized account name.
A34: [FieldDefinition] | B34: [EntityDefinition] | C34: OCE__CallExpense__c | D34: 01I3X000001zXyX.UserRecordAccess | E34: Object Access Level | F34: UserRecordAccessId | G34: Lookup(User Record Access) | H34: UserRecordAccess | J34: 18 | K34: 0 | L34: id | M34: false | N34: true | O34: false | P34: false | Q34: false | R34: false
A35: [FieldDefinition] | B35: [EntityDefinition] | C35: OCE__CallExpense__c | D35: 01I3X000001zXyX.SystemModstamp | E35: System Modstamp | F35: SystemModstamp | G35: Date/Time | J35: 0 | K35: 0 | L35: datetime | M35: true | N35: false | O35: false | P35: false | Q35: false | R35: false
A36: [FieldDefinition] | B36: [EntityDefinition] | C36: OCE__CallExpense__c | D36: 01I3X000001zXyX.Owner | E36: Owner | F36: OwnerId | G36: Lookup(User,Group) | H36: Owner | J36: 18 | K36: 0 | L36: id | M36: true | N36: false | O36: false | P36: false | Q36: false | R36: false
A37: [FieldDefinition] | B37: [EntityDefinition] | C37: OCE__CallExpense__c | D37: 01I3X000001zXyX.Name | E37: Interaction Expense Name | F37: Name | G37: Auto Number | J37: 80 | K37: 0 | L37: string | M37: true | N37: false | O37: false | P37: false | Q37: false | R37: false
A38: [FieldDefinition] | B38: [EntityDefinition] | C38: OCE__CallExpense__c | D38: 01I3X000001zXyX.LastModifiedDate | E38: Last Modified Date | F38: LastModifiedDate | G38: Date/Time | J38: 0 | K38: 0 | L38: datetime | M38: false | N38: false | O38: false | P38: false | Q38: false | R38: false
A39: [FieldDefinition] | B39: [EntityDefinition] | C39: OCE__CallExpense__c | D39: 01I3X000001zXyX.LastModifiedBy | E39: Last Modified By | F39: LastModifiedById | G39: Lookup(User) | H39: LastModifiedBy | J39: 18 | K39: 0 | L39: id | M39: false | N39: false | O39: false | P39: false | Q39: false | R39: false
A40: [FieldDefinition] | B40: [EntityDefinition] | C40: OCE__CallExpense__c | D40: 01I3X000001zXyX.LastActivityDate | E40: Last Activity Date | F40: LastActivityDate | G40: Date | J40: 0 | K40: 0 | L40: date | M40: false | N40: true | O40: false | P40: false | Q40: false | R40: false
...

Sheet TGT - Vault CRM Object Fields
A1: Object Name | B1: Object Label | C1: Field Name | D1: Field Label | E1: Field Type | F1: Field Description
A2: call2__v | B2: Call | C2: account__v | D2: Account | E2: Object | F2: Lookup to the account that the call is associated with.
A3: call2__v | B3: Call | C3: account_credentials__v | D3: Credentials | E3: Picklist
A4: call2__v | B4: Call | C4: account_identifier__v | D4: Account Identifier | E4: String
A5: call2__v | B5: Call | C5: account_plan__v | D5: Account Plan | E5: Object | F5: Lookup to account plan associated with this call. This field is optional.
A6: call2__v | B6: Call | C6: add_detail__v | D6: Add Detail | E6: LongText | F6: Field used to assist in the creation of Call2 Detail records to a Call2 record. The 18-digit Product Ids are ordered from left to right and are comma-delimited. The field will be blanked out after each save. A trigger on Call2 Header will parse the delim
A7: call2__v | B7: Call | C7: add_key_message__v | D7: Add Key Message | E7: LongText | F7: Field used to assist in the creation of Call2 Key Message records for a Call2 record. Input format is a list delimited by ";;;" of the following five fields (the last two, though, are optional) that are separated by "@@" - <Key_Message_ID>@@<Product_ID>@@
A8: call2__v | B8: Call | C8: address__v | D8: Address | E8: LongText | F8: A field used to denormalize the address information associated with a call. This aids in data loading and displaying information on related lists.
A9: call2__v | B9: Call | C9: address_line_1__v | D9: Address Line 1 | E9: String | F9: Address Line 1 of the Call Address. This field should not be displayed on the Page Layout.
A10: call2__v | B10: Call | C10: address_line_2__v | D10: Address Line 2 | E10: String | F10: Address Line 2 of the Call Address. This field should not be displayed on the Page Layout.
A11: call2__v | B11: Call | C11: allowed_products__v | D11: Allowed Products | E11: LongText
A12: call2__v | B12: Call | C12: assigner__v | D12: Assigner | E12: Object
A13: call2__v | B13: Call | C13: assignment_datetime__v | D13: Assignment Datetime | E13: DateTime
A14: call2__v | B14: Call | C14: assmca__v | D14: ASSMCA | E14: String | F14: The ASSMCA # is a license number when sampling controlled substances for a Puerto Rican-based Physician.
A15: call2__v | B15: Call | C15: attendee_list__v | D15: Other Non-HCP Attendees | E15: LongText | F15: This text field is a semi colon delimited list of Non-HCP attendees who were on this call. This text field can be displayed in Concur so that the User can then match to other Non-HCPs later.
A16: call2__v | B16: Call | C16: attendee_post_status__v | D16: Attendee Post Status | E16: String | F16: This field was included as an option in v14. It is no longer being utilized in the current version of the integration and is not part of the standard connector.
A17: call2__v | B17: Call | C17: attendee_type__v | D17: Attendee Type | E17: Picklist | F17: The type of entity who the call is created for. This field is used in reporting. For performance reasons, this is not set by an APEX trigger. For data import, this field should be set correctly otherwise reports that depend on this field may not run corr
A18: call2__v | B18: Call | C18: attendees__v | D18: Attendees | E18: Number | F18: The total number of attendees for this call. For a group call with four doctors, this would be "3" for the parent call associated to the parent account and "0" for the child calls. For performance reasons, this is not set via a trigger.
A19: call2__v | B19: Call | C19: call2_status__v | D19: Call Status | E19: Picklist
A20: call2__v | B20: Call | C20: call_channel__v | D20: Channel | E20: Picklist | F20: Specifies the channel of communication for this interaction.
A21: call2__v | B21: Call | C21: call_channel_formula__v | D21: Call Channel Formula | E21: String | F21: If a user has read FLS to this formula field, the result of the formula auto-populates call_channel__v. To use, replace OOTB formula with custom formula.
A22: call2__v | B22: Call | C22: call_comments__v | D22: Comments | E22: LongText | F22: Free text comments for call.
A23: call2__v | B23: Call | C23: call_date__v | D23: Date | E23: Date | F23: The date of the call when it was first saved or submitted. This field is set via a trigger to the current date if neither the date or datetime field is supplied.
A24: call2__v | B24: Call | C24: call_datetime__v | D24: Datetime | E24: DateTime | F24: The time when the rep specified for the call unless the call was signed, in which case this is the signature time. This field is optional for users who which to plan their calls down to a specific hour or minute. If a datetime is specified, a correspond
A25: call2__v | B25: Call | C25: call_reminder__v | D25: Call Reminder | E25: String
A26: call2__v | B26: Call | C26: call_type__v | D26: Call Type | E26: Picklist | F26: Type of call which is system maintained based on the type and contents of the call. This field is used for reporting purposes. Valid values are: Detail Only, Detail with Sample, Group Detail, Group Detail with Sample, Sample Only. These values should not
A27: call2__v | B27: Call | C27: cds__v | D27: CDS # | E27: String
A28: call2__v | B28: Call | C28: cds_expiration_date__v | D28: CDS Expiration Date | E28: Date
A29: call2__v | B29: Call | C29: chat_summary__v | D29: Chat Summary | E29: LongText
A30: call2__v | B30: Call | C30: check_in_latitude__v | D30: Check In Latitude | E30: Number
A31: call2__v | B31: Call | C31: check_in_location_services_status__v | D31: Check In Location Services Status | E31: Picklist
A32: call2__v | B32: Call | C32: check_in_longitude__v | D32: Check In Longitude | E32: Number
A33: call2__v | B33: Call | C33: check_in_status__v | D33: Check In Status | E33: Picklist
A34: call2__v | B34: Call | C34: check_in_timestamp__v | D34: Check In Timestamp | E34: Number
A35: call2__v | B35: Call | C35: child_account__v | D35: Child Account | E35: Object
A36: call2__v | B36: Call | C36: child_account_id__v | D36: Child Account Id | E36: String
A37: call2__v | B37: Call | C37: city__v | D37: City | E37: String | F37: City of the Call Address. This field should not be displayed on the Page Layout.
A38: call2__v | B38: Call | C38: clm__v | D38: CLM | E38: Boolean | F38: If checked indicates CLM has been run for this call and the call contents were populated from CLM.
A39: call2__v | B39: Call | C39: clm_location_latitude__v | D39: CLM Location Latitude | E39: Number
A40: call2__v | B40: Call | C40: clm_location_longitude__v | D40: CLM Location Longitude | E40: Number
...

Sheet Mapping Objects
A1: Source Objects | D1: Target Object | G1: OOB Mapping Status | H1: Custom Mapping Status | I1: Comments | J1: Additional notes | L1: Target Object
A2: Object | B2: Object Label | C2: Object Description | D2: Object | E2: Object Label | F2: Object Description | L2: Object | M2: Object Label | N2: Object Description | O2: Match Found?
A3: OCE__Call__c | B3: Interactions | C3: The Call object stores all data pertaining to Calls Reps have logged using the Log a Call module. | D3: call2__v | E3: =IFNA(IF(VLOOKUP(D3,L:N,2,FALSE)="","",VLOOKUP(D3,L:N,2,FALSE)),"") -> Call | F3: =IFNA(IF(VLOOKUP(D3,L:N,3,FALSE)="","",VLOOKUP(D3,L:N,3,FALSE)),"") -> This object stores the main call header information. There is one call row for every account or contact on the call. A group call with 3 doctors will produce 4 call rows. | G3: Reviewed with Roche | I3: Pending to review from Veeva and confirmation from field location_name__v | J3: In OCE-P the calls have in one single record the information from the HCP and the location-address, which is connected with the workplace (HCO). In Veeva we will need to create multiple records: - The visits without parent call and without any child call will be face to face. The Vault parent call will be the HCPs data and a new records will need to be created in Vault for the HCO as child call. - The visits with parent call will be group calls. The Vault parent call will be the HCOs data from the OCE-P location. The child call records will be the HCPs. | L3: call2__v | M3: Call | N3: This object stores the main call header information. There is one call row for every account or contact on the call. A group call with 3 doctors will produce 4 call rows. | O3: =IFNA(IF(VLOOKUP(L3,D:D,1,FALSE)=L3,"Yes","No"),"No") -> Yes
A4: OCE__CallEmployeeAttendee__c | B4: Call Employee Attendees | C4: Junction object which contains users which are added as attendees to call. | D4: call2__v | E4: =IFNA(IF(VLOOKUP(D4,L:N,2,FALSE)="","",VLOOKUP(D4,L:N,2,FALSE)),"") -> Call | F4: =IFNA(IF(VLOOKUP(D4,L:N,3,FALSE)="","",VLOOKUP(D4,L:N,3,FALSE)),"") -> This object stores the main call header information. There is one call row for every account or contact on the call. A group call with 3 doctors will produce 4 call rows. | G4: Reviewed with Roche | J4: This records will be child calls where attendees are users | L4: call2_detail__v | M4: Call Detail | N4: This object stores all product details data recorded on any call. | O4: =IFNA(IF(VLOOKUP(L4,D:D,1,FALSE)=L4,"Yes","No"),"No") -> Yes
A5: OCE__CallDetail__c | B5: Interaction Details | C5: The object stores data related to Details during the Call | D5: call2_detail__v | E5: =IFNA(IF(VLOOKUP(D5,L:N,2,FALSE)="","",VLOOKUP(D5,L:N,2,FALSE)),"") -> Call Detail | F5: =IFNA(IF(VLOOKUP(D5,L:N,3,FALSE)="","",VLOOKUP(D5,L:N,3,FALSE)),"") -> This object stores all product details data recorded on any call. | G5: Pending few fields to review with Roche | L5: action_item__v | M5: Call Discussion | N5: This object stores all product discussions data recorded on any call, as well as allows for creating different product discussions layouts | O5: =IFNA(IF(VLOOKUP(L5,D:D,1,FALSE)=L5,"Yes","No"),"No") -> Yes
A6: OCE__CallDiscussion__c | B6: Call Discussions | C6: The object stores data related to Discussions about products, during the Call | D6: call2_discussion__v | E6: =IFNA(IF(VLOOKUP(D6,L:N,2,FALSE)="","",VLOOKUP(D6,L:N,2,FALSE)),"") | F6: =IFNA(IF(VLOOKUP(D6,L:N,3,FALSE)="","",VLOOKUP(D6,L:N,3,FALSE)),"") | G6: Pending few fields to review with Roche | L6: call2_expense__v | M6: Call Expense | N6: This object stores all expense data recorded on a call | O6: =IFNA(IF(VLOOKUP(L6,D:D,1,FALSE)=L6,"Yes","No"),"No") -> No
A7: OCE__CallMessage__c | B7: Call Messages | C7: The object stores data related to messages/reactions during the Call | D7: call2_key_message__v | E7: =IFNA(IF(VLOOKUP(D7,L:N,2,FALSE)="","",VLOOKUP(D7,L:N,2,FALSE)),"") -> Call Key Message | F7: =IFNA(IF(VLOOKUP(D7,L:N,3,FALSE)="","",VLOOKUP(D7,L:N,3,FALSE)),"") -> This object stores all Key Messages recorded on a call | G7: Pending few fields to review with Roche | L7: call2_key_message__v | M7: Call Key Message | N7: This object stores all Key Messages recorded on a call | O7: =IFNA(IF(VLOOKUP(L7,D:D,1,FALSE)=L7,"Yes","No"),"No") -> Yes
A8: OCE__CallItem__c | B8: Call Items | C8: The object stores data related to Items during the Call | D8: call2_sample__v | E8: =IFNA(IF(VLOOKUP(D8,L:N,2,FALSE)="","",VLOOKUP(D8,L:N,2,FALSE)),"") -> Call Sample | F8: =IFNA(IF(VLOOKUP(D8,L:N,3,FALSE)="","",VLOOKUP(D8,L:N,3,FALSE)),"") -> Samples and Promotional Items itemized on Call Reports | G8: Reviewed with Roche | J8: Items are educational item materials (papers) delivered during call reporting. In Veeva maybe are Promotional Items from Call Sample | L8: call2_sample__v | M8: Call Sample | N8: Samples and Promotional Items itemized on Call Reports | O8: =IFNA(IF(VLOOKUP(L8,D:D,1,FALSE)=L8,"Yes","No"),"No") -> Yes
A9: OCE__CallPresentation__c | B9: Call Presentations | C9: The object stores data related to Presentations shown from Call, Meeting, etc. | D9: OOS | E9: =IFNA(IF(VLOOKUP(D9,L:N,2,FALSE)="","",VLOOKUP(D9,L:N,2,FALSE)),"") | F9: =IFNA(IF(VLOOKUP(D9,L:N,3,FALSE)="","",VLOOKUP(D9,L:N,3,FALSE)),"") | G9: Out of Scope | J9: In calls, the field presentations__v should contain the list of presentations (CLMs) related with OCE_CallPresentation__c per call. | L9: call2_sample_cancel__v | M9: Call Sample Cancel | N9: The Call Sample Cancel object provides the ability to Cancel the delivery of a Sample Send request for a physician. | O9: =IFNA(IF(VLOOKUP(L9,D:D,1,FALSE)=L9,"Yes","No"),"No") -> No
A10: OCE__ClickStreamMetric__c | B10: Click Stream Metric | C10: Used for gathering CLM clickstream data. | D10: OOS | E10: =IFNA(IF(VLOOKUP(D10,L:N,2,FALSE)="","",VLOOKUP(D10,L:N,2,FALSE)),"") | F10: =IFNA(IF(VLOOKUP(D10,L:N,3,FALSE)="","",VLOOKUP(D10,L:N,3,FALSE)),"") | G10: Out of Scope | J10: In calls, the field presentations__v should contain the list of presentations (CLMs) related with OCE_CallPresentation__c per call. | L10: call_clickstream__v | M10: Call Clickstream | N10: Object containing clickstream data received from CLM system. | O10: =IFNA(IF(VLOOKUP(L10,D:D,1,FALSE)=L10,"Yes","No"),"No") -> No
A11: OCE__ClickStreamMetric__c | B11: Click Stream Metric | C11: Used for gathering CLM clickstream data. | D11: call2_key_message__v | E11: =IFNA(IF(VLOOKUP(D11,L:N,2,FALSE)="","",VLOOKUP(D11,L:N,2,FALSE)),"") -> Call Key Message | F11: =IFNA(IF(VLOOKUP(D11,L:N,3,FALSE)="","",VLOOKUP(D11,L:N,3,FALSE)),"") -> This object stores all Key Messages recorded on a call | G11: Pending few fields to review with Roche | J11: In calls, the field presentations__v should contain the list of presentations (CLMs) related with OCE_CallPresentation__c per call. | L11: call_cycle_entry__v | M11: Call Cycle Entry | N11: Call Cycle Entries store information about a rep's weekly route. They only store account name, the default address for each account is used when the call cycle is applied to a day. Call cycles (and their titles) are only editable on VMobile. However, r | O11: =IFNA(IF(VLOOKUP(L11,D:D,1,FALSE)=L11,"Yes","No"),"No") -> No
A12: OCE__CallDialogue__c | B12: Interaction Dialogues | C12: Contains surveys passed on LogACall. | D12: OOS | E12: =IFNA(IF(VLOOKUP(D12,L:N,2,FALSE)="","",VLOOKUP(D12,L:N,2,FALSE)),"") | F12: =IFNA(IF(VLOOKUP(D12,L:N,3,FALSE)="","",VLOOKUP(D12,L:N,3,FALSE)),"") | G12: Out of Scope | J12: No historical data in scope | L12: call_error__v | M12: Call Error | N12: This is a temporary holding object for failed synchronization messages from the mobile client. The messages will be accepted or rejected by an administrator. | O12: =IFNA(IF(VLOOKUP(L12,D:D,1,FALSE)=L12,"Yes","No"),"No") -> No
A13: OCE__CallSampleOrder__c | B13: Call Sample Orders | C13: The object stores data related to Sample Orders during the Call | D13: call2_sample__v | E13: =IFNA(IF(VLOOKUP(D13,L:N,2,FALSE)="","",VLOOKUP(D13,L:N,2,FALSE)),"") -> Call Sample | F13: =IFNA(IF(VLOOKUP(D13,L:N,3,FALSE)="","",VLOOKUP(D13,L:N,3,FALSE)),"") -> Samples and Promotional Items itemized on Call Reports | G13: Pending few fields to review with Roche | J13: Are call samples send via logistic operator. Potentially can be the Veeva BRCs. | L13: call_followup_task__v | M13: Call Followup Task | N13: This is the user task object that stores records for call follow up activities. | O13: =IFNA(IF(VLOOKUP(L13,D:D,1,FALSE)=L13,"Yes","No"),"No") -> No
A14: OCE__CallStudy__c | B14: Interaction clinical trials | C14: Studies which were done during call. | D14: medical_insight__v | E14: =IFNA(IF(VLOOKUP(D14,L:N,2,FALSE)="","",VLOOKUP(D14,L:N,2,FALSE)),"") -> Medical Insight | F14: =IFNA(IF(VLOOKUP(D14,L:N,3,FALSE)="","",VLOOKUP(D14,L:N,3,FALSE)),"") -> Stores Key Medical Insights and relevant Insight sources | G14: Pending business decisions | I14: [20260423] Pending to decide the approach for this object migration. | J14: [20260423] Pending to decide the approach for this object migration. | L14: call_followup_template__v | M14: Call Followup Template | N14: A Call Follow-up Template controls how follow-up activities are created on Call Reports. One Template per Follow-up type (todo, medical information,...). | O14: =IFNA(IF(VLOOKUP(L14,D:D,1,FALSE)=L14,"Yes","No"),"No") -> No
A15: OCE__CallToDo__c | B15: Interaction To-Dos | C15: Junction object between Call and To-Do objects | D15: action_item__v | E15: =IFNA(IF(VLOOKUP(D15,L:N,2,FALSE)="","",VLOOKUP(D15,L:N,2,FALSE)),"") -> Call Discussion | F15: =IFNA(IF(VLOOKUP(D15,L:N,3,FALSE)="","",VLOOKUP(D15,L:N,3,FALSE)),"") -> This object stores all product discussions data recorded on any call, as well as allows for creating different product discussions layouts | G15: Pending business decisions | I15: [20260423] It's not yet discussed the approach for Account Plan, and this may have and impact on the management for this object, since it can be hadled via action_item__v, but also with call_followup_task__v or call2_objective__v. Next week it's planned a call from Veeva with business to decide on that. | J15: [20260423] It's not yet discussed the approach for Account Plan, and this may have and impact on the management for this object, since it can be hadled via action_item__v, but also with call_followup_task__v or call2_objective__v. Next week it's planned a call from Veeva with business to decide on that. | L15: call_objective__v | M15: Call Objective | N15: Call Objective can be accessed through Call Report | O15: =IFNA(IF(VLOOKUP(L15,D:D,1,FALSE)=L15,"Yes","No"),"No") -> No
A16: OCE__CallAccountTactic__c | B16: Interaction Tactics | C16: Junction object to connect Call to Tactics. | D16: call2_discussion__v | E16: =IFNA(IF(VLOOKUP(D16,L:N,2,FALSE)="","",VLOOKUP(D16,L:N,2,FALSE)),"") | F16: =IFNA(IF(VLOOKUP(D16,L:N,3,FALSE)="","",VLOOKUP(D16,L:N,3,FALSE)),"") | G16: Pending business decisions | I16: [20260423] To link an executed tactic during a call in Vault CRM should be done with action_item__v or with call2_objective__, which may or may not be connected with an Account Plan. Wait for next week meeting to review this topic. | J16: [20260423] To link an executed tactic during a call in Vault CRM should be done with action_item__v or with call2_objective__, which may or may not be connected with an Account Plan. Wait for next week meeting to review this topic. | L16: medical_insight__v | M16: Medical Insight | N16: Stores Key Medical Insights and relevant Insight sources | O16: =IFNA(IF(VLOOKUP(L16,D:D,1,FALSE)=L16,"Yes","No"),"No") -> Yes
A17: OCE__CallSample__c | B17: Call Samples | C17: The object stores data related to Samples during the Call | D17: OOS | E17: Call Sample | F17: Samples and Promotional Items itemized on Call Reports | G17: Out of Scope | J17: OCE_CallSample__c is empty but it's for F2F sample delivery. | L17: action_item__v | M17: Action Item | N17: Object used to represent a task that is associated to an account plan through the Account Plan hierarchy. | O17: =IFNA(IF(VLOOKUP(L17,D:D,1,FALSE)=L17,"Yes","No"),"No") -> Yes
A18: OCE__CallPlan__c | B18: Call Plans | C18: A strategic plan that is focused on reach and frequency. | D18: OOS | E18: =IFNA(IF(VLOOKUP(D18,L:N,2,FALSE)="","",VLOOKUP(D18,L:N,2,FALSE)),"") | F18: =IFNA(IF(VLOOKUP(D18,L:N,3,FALSE)="","",VLOOKUP(D18,L:N,3,FALSE)),"") | G18: Out of Scope
A19: OCE__CallExpense__c | B19: Call Expenses | C19: The object stores data related to Expenses during the Call | D19: OOS | E19: Call Expense | F19: This object stores all expense data recorded on a call | G19: Out of Scope | J19: OCE__CallExpense__c is empty

Sheet Sample_Data
A1: Person Call Parent
A2: SELECT FIELDS(ALL) from OCE__Call__c where OCE__ParentCall__c = null and OCE__Account__r.IsPersonAccount = true limit 200
A3: _ | B3: Id | C3: OwnerId | D3: IsDeleted | E3: Name | F3: CurrencyIsoCode | G3: RecordTypeId | H3: CreatedDate | I3: CreatedById | J3: LastModifiedDate | K3: LastModifiedById | L3: SystemModstamp | M3: LastViewedDate | N3: LastReferencedDate | O3: OCE__Accompaniedby__c | P3: OCE__AccountName__c | Q3: OCE__AccountRefData__c | R3: OCE__AccountRestrictedProductsByTerritories__c | S3: OCE__AccountRestrictedProducts__c | T3: OCE__AccountTerritories__c | U3: OCE__Account__c | V3: OCE__AddressLine1__c | W3: OCE__AddressLine2__c | X3: OCE__AddressLine3__c | Y3: OCE__AddressLine4__c | Z3: OCE__AttendeeStatus__c | AA3: OCE__AudioConferenceID__c | AB3: OCE__CSPExpirationDate__c | AC3: OCE__CSPnumber__c | AD3: OCE__CallAddress__c | AE3: OCE__CallDateTime__c | AF3: OCE__CallPlanRefData__c | AG3: OCE__CallPlan__c | AH3: OCE__CallShipToAddress__c | AI3: OCE__CallType__c | AJ3: OCE__Channel__c | AK3: OCE__ChildCallParams__c | AL3: OCE__City__c | AM3: OCE__DEAExpirationDate__c | AN3: OCE__DEALicenseAddress__c | AO3: OCE__DEASchedule__c | AP3: OCE__DEAStatus__c | AQ3: OCE__DEAnumber__c | AR3: OCE__Date__c | AS3: OCE__DisclaimerMessage__c | AT3: OCE__DurationPicklist__c | AU3: OCE__Duration__c | AV3: OCE__EndCallDateTime__c | AW3: OCE__ExpenseAmount__c | AX3: OCE__ExternalID__c | AY3: OCE__GeolocationCheckDateTimeOnSignature__c | AZ3: OCE__GeolocationCheckDateTimeOnSubmit__c | BA3: OCE__GeolocationMissingReasonOnSignature__c | BB3: OCE__GeolocationMissingReasonOnSubmit__c | BC3: OCE__GeolocationOnSignature__Latitude__s | BD3: OCE__GeolocationOnSignature__Longitude__s | BE3: OCE__GeolocationOnSignature__c | BF3: OCE__GeolocationOnSubmit__Latitude__s | BG3: OCE__GeolocationOnSubmit__Longitude__s | BH3: OCE__GeolocationOnSubmit__c | BI3: OCE__IntegrationID__c | BJ3: OCE__InvitationBouncedMessage__c | BK3: OCE__InvitationEmail__c | BL3: OCE__InvitationStatus__c | BM3: OCE__IsConfirmed__c | BN3: OCE__IsDeletedOffline__c | BO3: OCE__IsGroupCall__c | BP3: OCE__IsSignatureCopyRequested__c | BQ3: OCE__IssuesDiscussed__c | BR3: OCE__LicenseExpirationDate__c | BS3: OCE__LicenseStatus__c | BT3: OCE__Licensenumber__c | BU3: OCE__Location__c | BV3: OCE__ManagerComment__c | BW3: OCE__ManagerConfirmationDatetime__c | BX3: OCE__ManagerConfirmationRequest__c | BY3: OCE__ManagerPresenceConfirmed__c | BZ3: OCE__ManagerPresenceStatus__c | CA3: OCE__NextCallObjectivePicklist__c | CB3: OCE__NextCallObjective__c | CC3: OCE__NumberOfCallDetails__c | CD3: OCE__NumberOfCallSampleOrders__c | CE3: OCE__NumberOfCallSamples__c | CF3: OCE__Objections__c | CG3: OCE__OfflineCreatedByID__c | CH3: OCE__OfflineCreatedDate__c | CI3: OCE__OfflineLastModifiedByID__c | CJ3: OCE__OfflineLastModifiedDate__c | CK3: OCE__OfflineUniqueId__c | CL3: OCE__PDMATextInfo__c | CM3: OCE__ParentCallRefData__c | CN3: OCE__ParentCall__c | CO3: OCE__PhysicalFormReason__c | CP3: OCE__PhysicalForm__c | CQ3: OCE__PhysicianDEALicenseNo__c | CR3: OCE__PhysicianDEALicense__c | CS3: OCE__PhysicianStateLicenseNo__c | CT3: OCE__PhysicianStateLicense__c | CU3: OCE__PlannedDate__c | CV3: OCE__PreCallNotes__c | CW3: OCE__ProfessionalDesignation__c | CX3: OCE__RemoteExternalID__c | CY3: OCE__RequestManagerPresence__c | CZ3: OCE__RestrictedProductsOverride__c | DA3: OCE__RouteRefData__c | DB3: OCE__Route__c | DC3: OCE__SalesRepRefData__c | DD3: OCE__SalesRep__c | DE3: OCE__Salutation__c | DF3: OCE__SessionKey__c | DG3: OCE__ShipToAddressLine1__c | DH3: OCE__ShipToAddressLine2__c | DI3: OCE__ShipToCity__c | DJ3: OCE__ShipToRefData__c | DK3: OCE__ShipToState__c | DL3: OCE__ShipToZip__c | DM3: OCE__ShipTo__c | DN3: OCE__ShippingAddress__c | DO3: OCE__SignatureDate__c | DP3: OCE__SignatureTimestamp__c | DQ3: OCE__Signature__c | DR3: OCE__State__c | DS3: OCE__Status__c | DT3: OCE__Subject__c | DU3: OCE__SubmissionDate__c | DV3: OCE__SubmissionDelayReasonPicklist__c | DW3: OCE__SubmissionDelayReason__c | DX3: OCE__Territory__c | DY3: OCE__TotalCallAttendeeCount__c | DZ3: OCE__UniqueIntegrationID__c | EA3: OCE__UserAudioToken__c | EB3: OCE__WithdrawnDate__c | EC3: OCE__Zip__c | ED3: OCE__BookingStatus__c | EE3: OCE__RejectReason__c | EF3: OCE__ComplianceStatements__c | EG3: OCE__HasAttachments__c | EH3: OCE__NextCallProductObjectives__c | EI3: OCE__PreCallProductNotes__c | EJ3: RCH_Is_Unlocked__c | EK3: OCE__Meeting__c | EL3: OCE__Country__c | EM3: OCE__IsAdHocCall__c | EN3: OCE__ToDo__c | EO3: External_Link__c | EP3: RCH_AE_Disclaimer__c | EQ3: RCH_Account_Country__c | ER3: RCH_Account_Mdm_Id__c | ES3: RCH_Account_Name__c | ET3: RCH_Activity_Type__c | EU3: RCH_Activity_owner_Role__c | EV3: RCH_Adverse_Event_Number__c | EW3: RCH_Call_Date_Time_3_days__c | EX3: RCH_Call_Submitted_Entry_Delay_in_Days__c | EY3: RCH_Indication__c | EZ3: RCH_Interaction_Url__c | FA3: RCH_Is_Person_Account__c | FB3: RCH_Is_Signature_Sent__c | FC3: RCH_Is_Visible__c | FD3: RCH_NextInteractionProductObjective__c | FE3: RCH_No_Of_Days__c | FF3: RCH_Non_Visit__c | FG3: RCH_Number_of_Attendees__c | FH3: RCH_Owner_Email__c | FI3: RCH_Owner_FederationIdentifier__c | FJ3: RCH_Owner_Profile_Name__c | FK3: RCH_PC_Disclaimer__c | FL3: RCH_PEER_Activity__c | FM3: RCH_Product_Complaint_Number__c | FN3: RCH_Products__c | FO3: RCH_Profile__c | FP3: RCH_Response_Type__c | FQ3: RCH_Sub_Channel__c | FR3: RCH_TherapeuticArea__c | FS3: OCE1__AccountOneKeyID__c | FT3: RCH_gCal_Account_Name__c | FU3: RCH_gCal_Channel_Value__c | FV3: RCH_gCal_Count_of_Employee_Attendess__c | FW3: RCH_gCal_External_Id__c | FX3: RCH_gCal_HCP_Attendee_Count__c | FY3: RCH_AETrackerReocrdType__c | FZ3: RCH_Activity_Type_Sub_Type__c | GA3: RCH_Interaction_Nature__c | GB3: RCH_Response_Type_Promo__c | GC3: OCE__CallDetailProducts__c | GD3: OCE__ComplianceAgreementStatus__c | GE3: OCE__CallInformation__c | GF3: RCH_Is_Admin__c | GG3: HyperLink__c | GH3: RCH_Attendees__c | GI3: RCH_ChildStateModified__c | GJ3: RCH_Colleagues__c | GK3: RCH_gCal_Update_Interaction__c | GL3: RCH_Owner_Country__c | GM3: OCE1__CountryCode__c | GN3: OCE1__IsIntegrationUserContext__c | GO3: OCE1__WorkplaceOneKeyID__c | GP3: RCH_Owner_Timezone__c | GQ3: RCH_Description__c | GR3: RCH_OwnerName__c | GS3: RCH_Short_Description__c | GT3: RCH_VisitReason__c | GU3: RCH_EpiCX_Network_Attendees__c | GV3: RCH_RecordTypeName__c | GW3: RCH_Global_Sub_type__c | GX3: OCE1__LastModifiedBulkFormAndDate__c | GY3: EditDetailsFromCallCreate__c | GZ3: RCH_Call__c | HA3: RCH_Product_Messages__c | HB3: RCH_Sample_Products__c | HC3: RCH_Sub_type__c | HD3: OCE1__NextCallObjectives__c | HE3: OCE1__PrevCallObjectives__c | HF3: RCH_Linked_Call_Flag__c | HG3: RCH_Customer_to_be_surveyed__c | HH3: RCH_EmailTransaction__c
A4: [OCE__Call__c] | B4: a2Q6900000992d0EAA | C4: 0057U000001eKP1QAM | D4: false | E4: C-00312851 | F4: EUR | G4: 0123X000000wzbXQAQ | H4: 2023-11-03T14:49:37.000+0000 | I4: 0057U000001eKP1QAM | J4: 2024-06-19T12:56:19.000+0000 | K4: 0057U000001Yt7KQAS | L4: 2024-06-19T12:56:19.000+0000 | P4: Milica Neric | Q4: Milica Neric | R4: [] | S4: [] | U4: 0013X00003gWlCxQAK | V4: Brezovik Bb | AD4: Brezovik Bb, Nikšić, ME, 81400 | AE4: 2023-10-26T12:30:00.000+0000 | AI4: Detail Only | AJ4: Face To Face | AL4: Nikšić | AN4: false | AT4: 90 | AV4: 2023-10-26T14:00:00.000+0000 | AW4: 0 | BM4: false | BN4: false | BO4: false | BP4: false | BU4: a1J3X00000DYpE5UAL | BX4: false | BY4: false | CC4: 1 | CD4: 0 | CE4: 0 | CY4: false | CZ4: [{"isAllowAccount":false,"accId":"0013X00003gWlCxQAK"}] | DS4: Submitted | DU4: 2023-11-03T14:49:36.000+0000 | DX4: ME_CORE_TERR_007 | EC4: 81400 | EF4: [{"statementId":"a663X00000094MjQAI","statementType":"Note","statementLabel":"Documenting an Adverse event (AE), Special Situation (SS), Product complaints (PC) in CRM does not constitute a AE/SS/PC reporting to Drug Safety.","statementLabelText":"Documenting an Adverse event (AE), Special Situation (SS), Product complaints (PC) in CRM does not constitute a AE/SS/PC reporting to Drug Safety.","sortOrder":1},{"statementId":"a663X00000094MeQAI","statementType":"Note","statementLabel":"The information (in free text fields) must have been obtained legitimately and must be unambiguous, precise and clear. Only write facts, do not speculate","statementLabelText":"The information (in free text fields) must have been obtained legitimately and must be unambiguous, precise and clear. Only write facts, do not speculate","sortOrder":2}] | EG4: false | EJ4: false | EL4: ME | EM4: false | EP4: false | EQ4: ME | ET4: Call | EU4: Marketing | EW4: true | EX4: 8 | EZ4: https://roche-eu-oce--uat.sandbox.lightning.force.com/a2Q6900000992d0 | FA4: 1 | FB4: false | FC4: false | FE4: 5 | FF4: false | FG4: 1 | FH4: dijana.stojanovski@roche.com.invalid | FI4: rudovid1 | FJ4: Core Non Promotional Customer Facing | FK4: false | FL4: false | FN4: Tecentriq | FO4: Core Non Promotional Customer Facing | FP4: Proactive | FT4: Milica Neric | FU4: Face To Face | FY4: PV/HCO | GC4: Tecentriq | GE4: Tecentriq | GF4: true | GK4: false | GL4: ME | GM4: ME | GN4: false | GP4: Europe/Berlin | GR4: Dijana Stojanovski | GV4: Non-Promotional Face To Face | GY4: true | HF4: false
A5: [OCE__Call__c] | B5: a2Q69000009AIAKEA4 | C5: 0057U000001eKP1QAM | D5: false | E5: C-00422115 | F5: EUR | G5: 0123X000000wzbXQAQ | H5: 2024-01-26T15:34:07.000+0000 | I5: 0057U000001eKP1QAM | J5: 2024-01-26T15:35:50.000+0000 | K5: 0053X00000BBu6fQAD | L5: 2024-01-26T15:35:50.000+0000 | P5: Milica Neric | U5: 0013X00003gWlCxQAK | V5: Brezovik Bb | AD5: Brezovik Bb, Nikšić, ME, 81400 | AE5: 2024-01-23T11:45:00.000+0000 | AJ5: Face To Face | AL5: Nikšić | AN5: false | AT5: 60 | AV5: 2024-01-23T12:45:00.000+0000 | BM5: false | BN5: false | BO5: false | BP5: false | BU5: a1J3X00000DYpE5UAL | BX5: false | BY5: false | CC5: 1 | CD5: 0 | CE5: 0 | CY5: false | DS5: Submitted | DU5: 2024-01-26T15:35:43.000+0000 | DX5: ME_CORE_TERR_007 | EC5: 81400 | EF5: [{"statementValidationType":"None","statementValidationResponse":"Skipped","statementType":"Note","statementLabelText":"Documenting Adverse Events (AE), Special Situations (SS), or Product Complaints (PC), in CRM does not constitute AE/SS/PC reporting to Drug Safety.","statementLabel":"Documenting Adverse Events (AE), Special Situations (SS), or Product Complaints (PC), in CRM does not constitute AE/SS/PC reporting to Drug Safety.","statementId":"a6669000007KfNLAA0","sortOrder":1},{"statementValidationType":"None","statementValidationResponse":"Skipped","statementType":"Note","statementLabelText":"The information (in free text fields) must have been obtained legitimately and must be unambiguous, precise and clear. Only write facts, do not speculate","statementLabel":"The information (in free text fields) must have been obtained legitimately and must be unambiguous, precise and clear. Only write facts, do not speculate","statementId":"a6669000007KfNMAA0","sortOrder":2}] | EG5: false | EH5: [ ] | EJ5: false | EL5: ME | EM5: false | EP5: false | EQ5: ME | ET5: Call | EU5: Marketing | EW5: true | EX5: 3 | EZ5: https://roche-eu-oce--uat.sandbox.lightning.force.com/a2Q69000009AIAK | FA5: 1 | FB5: false | FC5: false | FE5: 5 | FF5: false | FG5: 3 | FH5: dijana.stojanovski@roche.com.invalid | FI5: rudovid1 | FJ5: Core Non Promotional Customer Facing | FK5: false | FL5: false | FN5: Tecentriq | FO5: Core Non Promotional Customer Facing | FP5: Proactive | FQ5: Group Interaction | FT5: Milica Neric | FU5: Face To Face | FX5: 1 | FY5: PV/HCO | GC5: Tecentriq | GD5: Not Required | GE5: Tecentriq | GF5: true | GK5: false | GL5: ME | GM5: ME | GN5: false | GP5: Europe/Berlin | GR5: Dijana Stojanovski | GV5: Non-Promotional Face To Face | GY5: true | HF5: false
A6: [OCE__Call__c] | B6: a2Q69000009DINWEA4 | C6: 0057U000001eKP1QAM | D6: false | E6: C-00069579 | F6: EUR | G6: 0123X000000wzbXQAQ | H6: 2023-04-14T22:21:05.000+0000 | I6: 0057U000001eKP1QAM | J6: 2024-06-19T11:18:14.000+0000 | K6: 0057U000001Yt7KQAS | L6: 2024-06-19T11:18:14.000+0000 | P6: Milica Pejovic | Q6: Milica Pejovic | R6: [] | S6: [] | U6: 0013X00003gWlCxQAK | V6: BREZOVIK BB | AD6: BREZOVIK BB, Nikšić, ME, 81400 | AE6: 2023-04-05T23:30:00.000+0000 | AI6: Detail Only | AJ6: Face To Face | AL6: Nikšić | AN6: false | AT6: 30 | AV6: 2023-04-06T00:00:00.000+0000 | AW6: 0 | BM6: false | BN6: false | BO6: false | BP6: false | BU6: a1J3X00000DYpE5UAL | BX6: false | BY6: false | CC6: 1 | CD6: 0 | CE6: 0 | CY6: false | CZ6: [{"isAllowAccount":false,"accId":"0013X00003gWlCxQAK"}] | DS6: Submitted | DU6: 2023-04-14T22:21:05.000+0000 | DX6: ME_CORE_TERR_007 | EC6: 81400 | EF6: [{"statementId":"a663X00000094MjQAI","statementType":"Note","statementLabel":"Documenting an Adverse event (AE), Special Situation (SS), Product complaints (PC) in CRM does not constitute a AE/SS/PC reporting to Drug Safety.","statementLabelText":"Documenting an Adverse event (AE), Special Situation (SS), Product complaints (PC) in CRM does not constitute a AE/SS/PC reporting to Drug Safety.","sortOrder":1},{"statementId":"a663X00000094MeQAI","statementType":"Note","statementLabel":"The information (in free text fields) must have been obtained legitimately and must be unambiguous, precise and clear. Only write facts, do not speculate","statementLabelText":"The information (in free text fields) must have been obtained legitimately and must be unambiguous, precise and clear. Only write facts, do not speculate","sortOrder":2}] | EG6: false | EJ6: false | EL6: ME | EM6: false | EP6: false | EQ6: ME | ET6: Call | EU6: Marketing | EW6: true | EX6: 9 | EY6: Lung Cancer | EZ6: https://roche-eu-oce--uat.sandbox.lightning.force.com/a2Q69000009DINW | FA6: 1 | FB6: false | FC6: false | FE6: 5 | FF6: false | FG6: 1 | FH6: dijana.stojanovski@roche.com.invalid | FI6: rudovid1 | FJ6: Core Non Promotional Customer Facing | FK6: false | FL6: false | FN6: Alecensa | FO6: Core Non Promotional Customer Facing | FP6: Proactive | FT6: Milica Neric | FU6: Face To Face | FY6: PV/HCO | GC6: Alecensa-Lung Cancer | GE6: Alecensa-Lung Cancer | GF6: true | GK6: false | GL6: ME | GM6: ME | GN6: false | GP6: Europe/Berlin | GR6: Dijana Stojanovski | GV6: Non-Promotional Face To Face | GY6: true | HF6: false
A7: [OCE__Call__c] | B7: a2Q69000009DIO5EAO | C7: 0057U000001eKP1QAM | D7: false | E7: C-00069589 | F7: EUR | G7: 0123X000000wzbXQAQ | H7: 2023-04-14T22:50:58.000+0000 | I7: 0057U000001eKP1QAM | J7: 2024-06-19T11:18:14.000+0000 | K7: 0057U000001Yt7KQAS | L7: 2024-06-19T11:18:14.000+0000 | P7: Milica Pejovic | Q7: Milica Pejovic | R7: [] | S7: [] | U7: 0013X00003gWlCxQAK | V7: BREZOVIK BB | AD7: BREZOVIK BB, Nikšić, ME, 81400 | AE7: 2023-03-08T23:00:00.000+0000 | AI7: Detail Only | AJ7: Face To Face | AL7: Nikšić | AN7: false | AT7: 75 | AV7: 2023-03-09T00:15:00.000+0000 | AW7: 0 | BM7: false | BN7: false | BO7: false | BP7: false | BU7: a1J3X00000DYpE5UAL | BX7: false | BY7: false | CC7: 1 | CD7: 0 | CE7: 0 | CY7: false | CZ7: [{"isAllowAccount":false,"accId":"0013X00003gWlCxQAK"}] | DS7: Submitted | DU7: 2023-04-14T22:50:57.000+0000 | DX7: ME_CORE_TERR_007 | EC7: 81400 | EF7: [{"statementId":"a663X00000094MjQAI","statementType":"Note","statementLabel":"Documenting an Adverse event (AE), Special Situation (SS), Product complaints (PC) in CRM does not constitute a AE/SS/PC reporting to Drug Safety.","statementLabelText":"Documenting an Adverse event (AE), Special Situation (SS), Product complaints (PC) in CRM does not constitute a AE/SS/PC reporting to Drug Safety.","sortOrder":1},{"statementId":"a663X00000094MeQAI","statementType":"Note","statementLabel":"The information (in free text fields) must have been obtained legitimately and must be unambiguous, precise and clear. Only write facts, do not speculate","statementLabelText":"The information (in free text fields) must have been obtained legitimately and must be unambiguous, precise and clear. Only write facts, do not speculate","sortOrder":2}] | EG7: false | EJ7: false | EL7: ME | EM7: false | EP7: false | EQ7: ME | ET7: Call | EU7: Marketing | EW7: true | EX7: 37 | EZ7: https://roche-eu-oce--uat.sandbox.lightning.force.com/a2Q69000009DIO5 | FA7: 1 | FB7: false | FC7: false | FE7: 5 | FF7: false | FG7: 1 | FH7: dijana.stojanovski@roche.com.invalid | FI7: rudovid1 | FJ7: Core Non Promotional Customer Facing | FK7: false | FL7: false | FN7: Tecentriq | FO7: Core Non Promotional Customer Facing | FP7: Proactive | FT7: Milica Neric | FU7: Face To Face | FY7: PV/HCO | GC7: Tecentriq | GE7: Tecentriq | GF7: true | GK7: false | GL7: ME | GM7: ME | GN7: false | GP7: Europe/Berlin | GR7: Dijana Stojanovski | GV7: Non-Promotional Face To Face | GY7: true | HF7: false
A8: [OCE__Call__c] | B8: a2Q69000009QbZCEA0 | C8: 0057U000001eKP1QAM | D8: false | E8: C-00170935 | F8: EUR | G8: 0123X000000wzbXQAQ | H8: 2023-07-27T05:44:22.000+0000 | I8: 0057U000001eKP1QAM | J8: 2024-06-19T09:59:43.000+0000 | K8: 0057U000001Yt7KQAS | L8: 2024-06-19T09:59:43.000+0000 | P8: Milica Pejovic | Q8: Milica Pejovic | R8: [] | S8: [] | U8: 0013X00003gWlCxQAK | V8: BREZOVIK BB | AD8: BREZOVIK BB, Nikšić, ME, 81400 | AE8: 2023-07-25T10:15:00.000+0000 | AI8: Detail Only | AJ8: Face To Face | AL8: Nikšić | AN8: false | AT8: 75 | AV8: 2023-07-25T11:30:00.000+0000 | AW8: 0 | BM8: false | BN8: false | BO8: false | BP8: false | BU8: a1J3X00000DYpE5UAL | BX8: false | BY8: false | CC8: 1 | CD8: 0 | CE8: 0 | CY8: false | CZ8: [{"isAllowAccount":false,"accId":"0013X00003gWlCxQAK"}] | DS8: Submitted | DU8: 2023-07-27T16:59:01.000+0000 | DX8: ME_CORE_TERR_007 | EC8: 81400 | EF8: [{"statementId":"a663X00000094MjQAI","statementType":"Note","statementLabel":"Documenting an Adverse event (AE), Special Situation (SS), Product complaints (PC) in CRM does not constitute a AE/SS/PC reporting to Drug Safety.","statementLabelText":"Documenting an Adverse event (AE), Special Situation (SS), Product complaints (PC) in CRM does not constitute a AE/SS/PC reporting to Drug Safety.","sortOrder":1},{"statementId":"a663X00000094MeQAI","statementType":"Note","statementLabel":"The information (in free text fields) must have been obtained legitimately and must be unambiguous, precise and clear. Only write facts, do not speculate","statementLabelText":"The information (in free text fields) must have been obtained legitimately and must be unambiguous, precise and clear. Only write facts, do not speculate","sortOrder":2}] | EG8: false | EJ8: false | EL8: ME | EM8: false | EP8: false | EQ8: ME | ET8: Call | EU8: Marketing | EW8: false | EX8: 2 | EY8: Lung Cancer | EZ8: https://roche-eu-oce--uat.sandbox.lightning.force.com/a2Q69000009QbZC | FA8: 1 | FB8: false | FC8: false | FE8: 5 | FF8: false | FG8: 1 | FH8: dijana.stojanovski@roche.com.invalid | FI8: rudovid1 | FJ8: Core Non Promotional Customer Facing | FK8: false | FL8: false | FO8: Core Non Promotional Customer Facing | FP8: Proactive | FT8: Milica Neric | FU8: Face To Face | FY8: PV/HCO | GC8: Lung Cancer | GE8: Lung Cancer | GF8: true | GK8: false | GL8: ME | GM8: ME | GN8: false | GP8: Europe/Berlin | GR8: Dijana Stojanovski | GV8: Non-Promotional Face To Face | GY8: true | HF8: false
A9: [OCE__Call__c] | B9: a2Q69000009Yi1vEAC | C9: 0057U000001eKP1QAM | D9: false | E9: C-00192122 | F9: EUR | G9: 0123X000000wzbXQAQ | H9: 2023-08-18T12:18:18.000+0000 | I9: 0057U000001eKP1QAM | J9: 2024-06-19T12:51:13.000+0000 | K9: 0057U000001Yt7KQAS | L9: 2024-06-19T12:51:13.000+0000 | P9: Milica Pejovic | Q9: Milica Pejovic | R9: [] | S9: [] | U9: 0013X00003gWlCxQAK | V9: Brezovik Bb | AD9: Brezovik Bb, Nikšić, ME, 81400 | AE9: 2023-08-18T09:15:00.000+0000 | AI9: Detail Only | AJ9: Face To Face | AL9: Nikšić | AN9: false | AT9: 30 | AV9: 2023-08-18T09:45:00.000+0000 | AW9: 0 | BM9: false | BN9: false | BO9: false | BP9: false | BU9: a1J3X00000DYpE5UAL | BX9: false | BY9: false | CC9: 1 | CD9: 0 | CE9: 0 | CY9: false | CZ9: [{"isAllowAccount":false,"accId":"0013X00003gWlCxQAK"}] | DS9: Submitted | DU9: 2023-09-01T12:52:31.000+0000 | DX9: ME_CORE_TERR_007 | EC9: 81400 | EF9: [{"statementId":"a663X00000094MjQAI","statementType":"Note","statementLabel":"Documenting an Adverse event (AE), Special Situation (SS), Product complaints (PC) in CRM does not constitute a AE/SS/PC reporting to Drug Safety.","statementLabelText":"Documenting an Adverse event (AE), Special Situation (SS), Product complaints (PC) in CRM does not constitute a AE/SS/PC reporting to Drug Safety.","sortOrder":1},{"statementId":"a663X00000094MeQAI","statementType":"Note","statementLabel":"The information (in free text fields) must have been obtained legitimately and must be unambiguous, precise and clear. Only write facts, do not speculate","statementLabelText":"The information (in free text fields) must have been obtained legitimately and must be unambiguous, precise and clear. Only write facts, do not speculate","sortOrder":2}] | EG9: false | EJ9: false | EL9: ME | EM9: false | EP9: false | EQ9: ME | ET9: Call | EU9: Marketing | EW9: true | EX9: 14 | EY9: Lung Cancer | EZ9: https://roche-eu-oce--uat.sandbox.lightning.force.com/a2Q69000009Yi1v | FA9: 1 | FB9: false | FC9: false | FE9: 5 | FF9: false | FG9: 1 | FH9: dijana.stojanovski@roche.com.invalid | FI9: rudovid1 | FJ9: Core Non Promotional Customer Facing | FK9: false | FL9: false | FN9: Alecensa | FO9: Core Non Promotional Customer Facing | FP9: Proactive | FT9: Milica Neric | FU9: Face To Face | FY9: PV/HCO | GC9: Alecensa-Lung Cancer | GE9: Alecensa-Lung Cancer | GF9: true | GK9: false | GL9: ME | GM9: ME | GN9: false | GP9: Europe/Berlin | GR9: Dijana Stojanovski | GV9: Non-Promotional Face To Face | GY9: true | HF9: false
